Workbook

Sheet Extraction
A1: RNA-DNA extraction | J1: Samples | L1: Sample Identifier | M1: extraction notes | N1: Row | O1: Column
A2: Date | B2: 20241212 | C2: date this plate was extracted: YYYYMMDD | I2: 1 | J2: 22MB00150 | L2: =J2 -> 22MB00150 | N2: A | O2: 1
I3: 2 | J3: 22MB00151 | L3: =J3 -> 22MB00151 | N3: A | O3: 2
A4: Plate # | C4: plate number (if multiple on same day) | I4: 3 | J4: 22MB00152 | L4: =J4 -> 22MB00152 | N4: A | O4: 3
I5: 4 | J5: 22MB00153 | L5: =J5 -> 22MB00153 | N5: A | O5: 4
A6: Initials | B6: SNH | C6: initials of extractor | I6: 5 | J6: 22MB00154 | L6: =J6 -> 22MB00154 | N6: A | O6: 5
I7: 6 | J7: 22MB00155 | L7: =J7 -> 22MB00155 | N7: A | O7: 6
B8: =CONCATENATE("RNA-DNA_",$B$2,"_",$B$4,"_",B6) -> RNA-DNA_20241212__SNH | I8: 7 | J8: 22MB00156 | L8: =J8 -> 22MB00156 | N8: A | O8: 7
I9: 8 | J9: 22MB00157 | L9: =J9 -> 22MB00157 | N9: A | O9: 8
A10: Plate notes | B10: Samples are from season 2022 in Cordova, AK (samples 22MB00150 - 22MB00160). *Will add 300ul VTM to 2022 Cordova samples due to faulty vials and leakage. Rest of samples are from season 2023 in Cordova, AK (samples 23MB00201 - 23MB00277 | I10: 9 | J10: 22MB00158 | L10: =J10 -> 22MB00158 | N10: A | O10: 9
I11: 10 | J11: 22MB00159 | L11: =J11 -> 22MB00159 | N11: A | O11: 10
I12: 11 | J12: 22MB00160 | L12: =J12 -> 22MB00160 | N12: A | O12: 11
I13: 12 | J13: 23MB00201 | L13: VTM-1 | M13: negative control | N13: A | O13: 12
I14: 13 | J14: 23MB00202 | L14: =J13 -> 23MB00201 | N14: B | O14: 1
I15: 14 | J15: 23MB00203 | L15: =J14 -> 23MB00202 | N15: B | O15: 2
I16: 15 | J16: 23MB00204 | L16: =J15 -> 23MB00203 | N16: B | O16: 3
I17: 16 | J17: 23MB00205 | L17: =J16 -> 23MB00204 | N17: B | O17: 4
I18: 17 | J18: 23MB00206 | L18: =J17 -> 23MB00205 | N18: B | O18: 5
I19: 18 | J19: 23MB00207 | L19: =J18 -> 23MB00206 | N19: B | O19: 6
I20: 19 | J20: 23MB00208 | L20: =J19 -> 23MB00207 | N20: B | O20: 7
I21: 20 | J21: 23MB00209 | L21: =J20 -> 23MB00208 | N21: B | O21: 8
I22: 21 | J22: 23MB00210 | L22: =J21 -> 23MB00209 | N22: B | O22: 9
A23: Extraction kit | B23: Omega Bio-tek Universal Pathogen Core Kit | I23: 22 | J23: 23MB00211 | L23: =J22 -> 23MB00210 | N23: B | O23: 10
I24: 23 | J24: 23MB00212 | L24: =J23 -> 23MB00211 | N24: B | O24: 11
I25: 24 | J25: 23MB00213 | L25: VTM-2 | M25: negative control | N25: B | O25: 12
I26: 25 | J26: 23MB00214 | L26: =J24 -> 23MB00212 | N26: C | O26: 1
I27: 26 | J27: 23MB00215 | L27: =J25 -> 23MB00213 | N27: C | O27: 2
I28: 27 | J28: 23MB00216 | L28: =J26 -> 23MB00214 | N28: C | O28: 3
I29: 28 | J29: 23MB00217 | L29: =J27 -> 23MB00215 | N29: C | O29: 4
I30: 29 | J30: 23MB00218 | L30: =J28 -> 23MB00216 | N30: C | O30: 5
I31: 30 | J31: 23MB00219 | L31: =J29 -> 23MB00217 | N31: C | O31: 6
I32: 31 | J32: 23MB00220 | L32: =J30 -> 23MB00218 | N32: C | O32: 7
I33: 32 | J33: 23MB00221 | L33: =J31 -> 23MB00219 | N33: C | O33: 8
I34: 33 | J34: 23MB00222 | L34: =J32 -> 23MB00220 | N34: C | O34: 9
I35: 34 | J35: 23MB00223 | L35: =J33 -> 23MB00221 | N35: C | O35: 10
I36: 35 | J36: 23MB00224 | L36: =J34 -> 23MB00222 | N36: C | O36: 11
I37: 36 | J37: 23MB00225 | L37: VTM-3 | M37: negative control | N37: C | O37: 12
I38: 37 | J38: 23MB00226 | L38: =J35 -> 23MB00223 | N38: D | O38: 1
I39: 38 | J39: 23MB00227 | L39: =J36 -> 23MB00224 | N39: D | O39: 2
I40: 39 | J40: 23MB00228 | L40: =J37 -> 23MB00225 | N40: D | O40: 3
...

Sheet RTPCR
A1: RT-PCR
A2: Date
A4: Plate Name | B4: =CONCATENATE("RTPCR_",Extraction!$B$2,"_",Extraction!$B$4) -> RTPCR_20241212_
A6: Initials
B9: 1 | C9: 2 | D9: 3 | E9: 4 | F9: 5 | G9: 6 | H9: 7 | I9: 8 | J9: 9 | K9: 10 | L9: 11 | M9: 12
A10: A | B10: =Extraction!$L2 -> 22MB00150 | C10: =Extraction!$L3 -> 22MB00151 | D10: =Extraction!$L4 -> 22MB00152 | E10: =Extraction!$L5 -> 22MB00153 | F10: =Extraction!$L6 -> 22MB00154 | G10: =Extraction!$L7 -> 22MB00155 | H10: =Extraction!$L8 -> 22MB00156 | I10: =Extraction!$L9 -> 22MB00157 | J10: =Extraction!$L10 -> 22MB00158 | K10: =Extraction!$L11 -> 22MB00159 | L10: =Extraction!$L12 -> 22MB00160 | M10: =Extraction!$L13 -> VTM-1
A11: B | B11: =Extraction!$L14 -> 23MB00201 | C11: =Extraction!$L15 -> 23MB00202 | D11: =Extraction!$L16 -> 23MB00203 | E11: =Extraction!$L17 -> 23MB00204 | F11: =Extraction!$L18 -> 23MB00205 | G11: =Extraction!$L19 -> 23MB00206 | H11: =Extraction!$L20 -> 23MB00207 | I11: =Extraction!$L21 -> 23MB00208 | J11: =Extraction!$L22 -> 23MB00209 | K11: =Extraction!$L23 -> 23MB00210 | L11: =Extraction!$L24 -> 23MB00211 | M11: =Extraction!$L25 -> VTM-2
A12: C | B12: =Extraction!$L26 -> 23MB00212 | C12: =Extraction!$L27 -> 23MB00213 | D12: =Extraction!$L28 -> 23MB00214 | E12: =Extraction!$L29 -> 23MB00215 | F12: =Extraction!$L30 -> 23MB00216 | G12: =Extraction!$L31 -> 23MB00217 | H12: =Extraction!$L32 -> 23MB00218 | I12: =Extraction!$L33 -> 23MB00219 | J12: =Extraction!$L34 -> 23MB00220 | K12: =Extraction!$L35 -> 23MB00221 | L12: =Extraction!$L36 -> 23MB00222 | M12: =Extraction!$L37 -> VTM-3
A13: D | B13: =Extraction!$L38 -> 23MB00223 | C13: =Extraction!$L39 -> 23MB00224 | D13: =Extraction!$L40 -> 23MB00225 | E13: =Extraction!$L41 -> 23MB00226 | F13: =Extraction!$L42 -> 23MB00227 | G13: =Extraction!$L43 -> 23MB00228 | H13: =Extraction!$L44 -> 23MB00229 | I13: =Extraction!$L45 -> 23MB00230 | J13: =Extraction!$L46 -> 23MB00231 | K13: =Extraction!$L47 -> 23MB00232 | L13: =Extraction!$L48 -> 23MB00233 | M13: =Extraction!$L49 -> VTM-4
A14: E | B14: =Extraction!$L50 -> 23MB00234 | C14: =Extraction!$L51 -> 23MB00235 | D14: =Extraction!$L52 -> 23MB00236 | E14: =Extraction!$L53 -> 23MB00237 | F14: =Extraction!$L54 -> 23MB00238 | G14: =Extraction!$L55 -> 23MB00239 | H14: =Extraction!$L56 -> 23MB00240 | I14: =Extraction!$L57 -> 23MB00241 | J14: =Extraction!$L58 -> 23MB00242 | K14: =Extraction!$L59 -> 23MB00243 | L14: =Extraction!$L60 -> 23MB00244 | M14: =Extraction!$L61 -> VTM-5
A15: F | B15: =Extraction!$L62 -> 23MB00245 | C15: =Extraction!$L63 -> 23MB00246 | D15: =Extraction!$L64 -> 23MB00247 | E15: =Extraction!$L65 -> 23MB00248 | F15: =Extraction!$L66 -> 23MB00249 | G15: =Extraction!$L67 -> 23MB00250 | H15: =Extraction!$L68 -> 23MB00251 | I15: =Extraction!$L69 -> 23MB00252 | J15: =Extraction!$L70 -> 23MB00253 | K15: =Extraction!$L71 -> 23MB00254 | L15: =Extraction!$L72 -> 23MB00255 | M15: =Extraction!$L73 -> VTM-6
A16: G | B16: =Extraction!$L74 -> 23MB00256 | C16: =Extraction!$L75 -> 23MB00257 | D16: =Extraction!$L76 -> 23MB00258 | E16: =Extraction!$L77 -> 23MB00259 | F16: =Extraction!$L78 -> 23MB00260 | G16: =Extraction!$L79 -> 23MB00261 | H16: =Extraction!$L80 -> 23MB00262 | I16: =Extraction!$L81 -> 23MB00263 | J16: =Extraction!$L82 -> 23MB00264 | K16: =Extraction!$L83 -> 23MB00265 | L16: =Extraction!$L84 -> 23MB00266 | M16: =Extraction!$L85 -> PR8
A17: H | B17: =Extraction!$L86 -> 23MB00267 | C17: =Extraction!$L87 -> 23MB00268 | D17: =Extraction!$L88 -> 23MB00269 | E17: =Extraction!$L89 -> 23MB00270 | F17: =Extraction!$L90 -> 23MB00271 | G17: =Extraction!$L91 -> 23MB00272 | H17: =Extraction!$L92 -> 23MB00273 | I17: =Extraction!$L93 -> 23MB00274 | J17: =Extraction!$L94 -> 23MB00275 | K17: =Extraction!$L95 -> 23MB00276 | L17: =Extraction!$L96 -> 23MB00277 | M17: PR8
A20: Reagent notes | B20: Reagent | D20: Calculations | G20: Date written on label (1st aliquot/bottle) | J20: Date written on label (2nd aliquot/bottle) | M20: Date written on label (3rd aliquot/bottle)
B22: Toughmix
B24: nuclease-free water
B26: forward primer
B28: reverse primer
B30: probe
B32: cDNA positive control (PR8)
A36: Plate notes

Sheet QS5
A1: * Block Type = 96-Well 0.1-mL Block
A2: * Date Created = Wed Jan 04 12:44:52 EST 2023
A3: * Passive Reference = ROX
A4: * Barcode =
A6: [Sample Setup]
A7: Well | B7: Well Position | C7: Sample Name | D7: Sample Color | E7: Biogroup Name | F7: Biogroup Color | G7: Target Name | H7: Target Color | I7: Task | J7: Reporter | K7: Quencher | L7: Quantity | M7: Comments
A8: 1 | B8: A1 | C8: =Extraction!L2 -> 22MB00150
A9: 2 | B9: A2 | C9: =Extraction!L3 -> 22MB00151
A10: 3 | B10: A3 | C10: =Extraction!L4 -> 22MB00152
A11: 4 | B11: A4 | C11: =Extraction!L5 -> 22MB00153
A12: 5 | B12: A5 | C12: =Extraction!L6 -> 22MB00154
A13: 6 | B13: A6 | C13: =Extraction!L7 -> 22MB00155
A14: 7 | B14: A7 | C14: =Extraction!L8 -> 22MB00156
A15: 8 | B15: A8 | C15: =Extraction!L9 -> 22MB00157
A16: 9 | B16: A9 | C16: =Extraction!L10 -> 22MB00158
A17: 10 | B17: A10 | C17: =Extraction!L11 -> 22MB00159
A18: 11 | B18: A11 | C18: =Extraction!L12 -> 22MB00160
A19: 12 | B19: A12 | C19: =Extraction!L13 -> VTM-1
... A103: 96 | B103: H12 | C103: =Extraction!L97 -> PR8

Sheet Sheet1

Sheet Results
A1: File Name | B1: /Users/jonathandain/Library/CloudStorage/OneDrive-UniversityofMassachusettsBoston/Temp_qPCR_Run_Files/qPCR_IAV_matrix_20241115.eds | C1: ...3 | D1: ...4 | E1: ...5 | F1: ...6 | G1: ...7 | H1: ...8 | I1: ...9 | J1: ...10 | K1: ...11 | L1: ...12 | M1: ...13 | N1: ...14 | O1: ...15 | P1: ...16 | Q1: ...17 | R1: ...18 | S1: ...19 | T1: ...20 | U1: ...21
A2: Comment
A3: Operator | B3: DEFAULT
A4: Barcode
A5: Instrument Type | B5: QuantStudio™ 5 System
A6: Block Type | B6: 96-Well 0.1-mL Block
A7: Instrument Name | B7: 272510305
A8: Instrument Serial Number | B8: 272510305
A9: Heated Cover Serial Number
A10: Block serial number | B10: 17081381
A11: Run Start Date/Time | B11: 2024-12-19 01:28:36 PM EST
A12: Run End Data/Time | B12: 2024-12-19 02:24:30 PM EST
A13: Run Duration | B13: 55 minutes 54 seconds
A14: Sample Volume | B14: 20.0
A15: Cover Temperature | B15: 105.0
A16: Passive Reference | B16: ROX
A17: PCR Stage/Step Number | B17: Stage 2 Step 2
A18: Quantification Cycle Method | B18: CT
A19: Analysis Date/Time | B19: 2025-01-03 02:44:41 PM EST
A20: Software Name and Version | B20: Design & Analysis Software v2.7.0
A21: Plugin Name and Version | B21: Primary Analysis v1.8.0, Standard Curve v1.7.0
... A23: Exported On | B23: 2025-01-03 02:46:13 PM EST
A25: Well | B25: Well Position | C25: Omit | D25: Sample | E25: Target | F25: Task | G25: Reporter | H25: Quencher | I25: Amp Status | J25: Amp Score | K25: Curve Quality | L25: Result Quality Issues | M25: Cq | N25: Cq Confidence | O25: Cq Mean | P25: Cq SD | Q25: Auto Threshold | R25: Threshold | S25: Auto Baseline | T25: Baseline Start | U25: Baseline End
A26: 3 | B26: A3 | C26: FALSE | D26: 22MB00064 | E26: IAV_matrix | F26: UNKNOWN | G26: FAM | H26: NFQ-MGB | I26: NO_AMP | J26: 0 | M26: UNDETERMINED | N26: 0 | Q26: TRUE | R26: 1.1678600632634439 | S26: TRUE | T26: 3 | U26: 44
A27: 4 | B27: A4 | C27: FALSE | D27: 22MB00065 | E27: IAV_matrix | F27: UNKNOWN | G27: FAM | H27: NFQ-MGB | I27: NO_AMP | J27: 0 | M27: UNDETERMINED | N27: 0 | Q27: TRUE | R27: 1.1678600632634439 | S27: TRUE | T27: 3 | U27: 44
A28: 5 | B28: A5 | C28: FALSE | D28: 22MB00066 | E28: IAV_matrix | F28: UNKNOWN | G28: FAM | H28: NFQ-MGB | I28: NO_AMP | J28: 0 | M28: UNDETERMINED | N28: 0 | Q28: TRUE | R28: 1.1678600632634439 | S28: TRUE | T28: 3 | U28: 44
A29: 6 | B29: A6 | C29: FALSE | D29: 22MB00067 | E29: IAV_matrix | F29: UNKNOWN | G29: FAM | H29: NFQ-MGB | I29: NO_AMP | J29: 0 | M29: UNDETERMINED | N29: 0 | Q29: TRUE | R29: 1.1678600632634439 | S29: TRUE | T29: 3 | U29: 44
A30: 7 | B30: A7 | C30: FALSE | D30: 22MB00068 | E30: IAV_matrix | F30: UNKNOWN | G30: FAM | H30: NFQ-MGB | I30: NO_AMP | J30: 0 | M30: UNDETERMINED | N30: 0 | Q30: TRUE | R30: 1.1678600632634439 | S30: TRUE | T30: 3 | U30: 44
A31: 8 | B31: A8 | C31: FALSE | D31: 22MB00069 | E31: IAV_matrix | F31: UNKNOWN | G31: FAM | H31: NFQ-MGB | I31: NO_AMP | J31: 0 | M31: UNDETERMINED | N31: 0 | Q31: TRUE | R31: 1.1678600632634439 | S31: TRUE | T31: 3 | U31: 44
A32: 9 | B32: A9 | C32: FALSE | D32: 22MB00070 | E32: IAV_matrix | F32: UNKNOWN | G32: FAM | H32: NFQ-MGB | I32: NO_AMP | J32: 0 | M32: UNDETERMINED | N32: 0 | Q32: TRUE | R32: 1.1678600632634439 | S32: TRUE | T32: 3 | U32: 44
A33: 10 | B33: A10 | C33: FALSE | D33: 22MB00071 | E33: IAV_matrix | F33: UNKNOWN | G33: FAM | H33: NFQ-MGB | I33: NO_AMP | J33: 0 | M33: UNDETERMINED | N33: 0 | Q33: TRUE | R33: 1.1678600632634439 | S33: TRUE | T33: 3 | U33: 44
A34: 11 | B34: A11 | C34: FALSE | D34: 22MB00072 | E34: IAV_matrix | F34: UNKNOWN | G34: FAM | H34: NFQ-MGB | I34: NO_AMP | J34: 0 | M34: UNDETERMINED | N34: 0 | Q34: TRUE | R34: 1.1678600632634439 | S34: TRUE | T34: 3 | U34: 44
A35: 12 | B35: A12 | C35: FALSE | D35: VTM-1 | E35: IAV_matrix | F35: NTC | G35: FAM | H35: NFQ-MGB | I35: NO_AMP | J35: 0 | M35: UNDETERMINED | N35: 0 | Q35: TRUE | R35: 1.1678600632634439 | S35: TRUE | T35: 3 | U35: 44
A36: 13 | B36: B1 | C36: FALSE | D36: 22MB00073 | E36: IAV_matrix | F36: UNKNOWN | G36: FAM | H36: NFQ-MGB | I36: NO_AMP | J36: 0 | M36: UNDETERMINED | N36: 0 | Q36: TRUE | R36: 1.1678600632634439 | S36: TRUE | T36: 3 | U36: 44
A37: 14 | B37: B2 | C37: FALSE | D37: 22MB00074 | E37: IAV_matrix | F37: UNKNOWN | G37: FAM | H37: NFQ-MGB | I37: NO_AMP | J37: 0.7064329440463335 | M37: UNDETERMINED | N37: 0 | Q37: TRUE | R37: 1.1678600632634439 | S37: TRUE | T37: 3 | U37: 32
... A106: 83 | B106: G11 | C106: FALSE | D106: 22MB00138 | E106: IAV_matrix | F106: UNKNOWN | G106: FAM | H106: NFQ-MGB | I106: NO_AMP | J106: 0 | M106: UNDETERMINED | N106: 0 | Q106: TRUE | R106: 1.1678600632634439 | S106: TRUE | T106: 3 | U106: 44
A107: 84 | B107: G12 | C107: FALSE | D107: PR8 | E107: IAV_matrix | F107: POSITIVE_CONTROL | G107: FAM | H107: NFQ-MGB | I107: AMP | J107: 1.6979965426506729 | M107: 12.156998001081018 | N107: 0.97221099314951165 | O107: 16.376863988926885 | P107: 5.9677917114085757 | Q107: TRUE | R107: 1.1678600632634439 | S107: TRUE | T107: 3 | U107: 5
A108: 85 | B108: H1 | C108: FALSE | D108: 22MB00139 | E108: IAV_matrix | F108: UNKNOWN | G108: FAM | H108: NFQ-MGB | I108: NO_AMP | J108: 0 | M108: UNDETERMINED | N108: 0 | Q108: TRUE | R108: 1.1678600632634439 | S108: TRUE | T108: 3 | U108: 44
A109: 86 | B109: H2 | C109: FALSE | D109: 22MB00140 | E109: IAV_matrix | F109: UNKNOWN | G109: FAM | H109: NFQ-MGB | I109: NO_AMP | J109: 0 | M109: UNDETERMINED | N109: 0 | Q109: TRUE | R109: 1.1678600632634439 | S109: TRUE | T109: 3 | U109: 44
A110: 87 | B110: H3 | C110: FALSE | D110: 22MB00141 | E110: IAV_matrix | F110: UNKNOWN | G110: FAM | H110: NFQ-MGB | I110: NO_AMP | J110: 0 | M110: UNDETERMINED | N110: 0 | Q110: TRUE | R110: 1.1678600632634439 | S110: TRUE | T110: 3 | U110: 44
...
