Workbook

Sheet Extraction
A1: RNA-DNA extraction | J1: Samples | L1: Sample Identifier | M1: extraction notes | N1: Row | O1: Column
A2: Date | B2: 20241212 | C2: date this plate was extracted: YYYYMMDD | I2: 1 | J2: 22MB00150 | L2: =J2 -> 22MB00150 | N2: A | O2: 1
I3: 2 | J3: 22MB00151 | L3: =J3 -> 22MB00151 | N3: A | O3: 2
A4: Plate # | C4: plate number (if multiple on same day) | I4: 3 | J4: 22MB00152 | L4: =J4 -> 22MB00152 | N4: A | O4: 3
I5: 4 | J5: 22MB00153 | L5: =J5 -> 22MB00153 | N5: A | O5: 4
A6: Initials | B6: SNH | C6: initials of extractor | I6: 5 | J6: 22MB00154 | L6: =J6 -> 22MB00154 | N6: A | O6: 5
I7: 6 | J7: 22MB00155 | L7: =J7 -> 22MB00155 | N7: A | O7: 6
B8: =CONCATENATE("RNA-DNA_",$B$2,"_",$B$4,"_",B6) -> RNA-DNA_20241212__SNH | I8: 7 | J8: 22MB00156 | L8: =J8 -> 22MB00156 | N8: A | O8: 7
I9: 8 | J9: 22MB00157 | L9: =J9 -> 22MB00157 | N9: A | O9: 8
A10: Plate notes | B10: Samples are from season 2022 in Cordova, AK (samples 22MB00150 - 22MB00160). *Will add 300ul VTM to 2022 Cordova samples due to faulty vials and leakage. Rest of samples are from season 2023 in Cordova, AK (samples 23MB00201 - 23MB00277 | I10: 9 | J10: 22MB00158 | L10: =J10 -> 22MB00158 | N10: A | O10: 9
I11: 10 | J11: 22MB00159 | L11: =J11 -> 22MB00159 | N11: A | O11: 10
I12: 11 | J12: 22MB00160 | L12: =J12 -> 22MB00160 | N12: A | O12: 11
I13: 12 | J13: 23MB00201 | L13: VTM-1 | M13: negative control | N13: A | O13: 12
I14: 13 | J14: 23MB00202 | L14: =J13 -> 23MB00201 | N14: B | O14: 1
I15: 14 | J15: 23MB00203 | L15: =J14 -> 23MB00202 | N15: B | O15: 2
I16: 15 | J16: 23MB00204 | L16: =J15 -> 23MB00203 | N16: B | O16: 3
I17: 16 | J17: 23MB00205 | L17: =J16 -> 23MB00204 | N17: B | O17: 4
I18: 17 | J18: 23MB00206 | L18: =J17 -> 23MB00205 | N18: B | O18: 5
I19: 18 | J19: 23MB00207 | L19: =J18 -> 23MB00206 | N19: B | O19: 6
I20: 19 | J20: 23MB00208 | L20: =J19 -> 23MB00207 | N20: B | O20: 7
I21: 20 | J21: 23MB00209 | L21: =J20 -> 23MB00208 | N21: B | O21: 8
I22: 21 | J22: 23MB00210 | L22: =J21 -> 23MB00209 | N22: B | O22: 9
A23: Extraction kit | B23: Omega Bio-tek Universal Pathogen Core Kit | I23: 22 | J23: 23MB00211 | L23: =J22 -> 23MB00210 | N23: B | O23: 10
I24: 23 | J24: 23MB00212 | L24: =J23 -> 23MB00211 | N24: B | O24: 11
I25: 24 | J25: 23MB00213 | L25: VTM-2 | M25: negative control | N25: B | O25: 12
I26: 25 | J26: 23MB00214 | L26: =J24 -> 23MB00212 | N26: C | O26: 1
I27: 26 | J27: 23MB00215 | L27: =J25 -> 23MB00213 | N27: C | O27: 2
I28: 27 | J28: 23MB00216 | L28: =J26 -> 23MB00214 | N28: C | O28: 3
I29: 28 | J29: 23MB00217 | L29: =J27 -> 23MB00215 | N29: C | O29: 4
I30: 29 | J30: 23MB00218 | L30: =J28 -> 23MB00216 | N30: C | O30: 5
I31: 30 | J31: 23MB00219 | L31: =J29 -> 23MB00217 | N31: C | O31: 6
I32: 31 | J32: 23MB00220 | L32: =J30 -> 23MB00218 | N32: C | O32: 7
I33: 32 | J33: 23MB00221 | L33: =J31 -> 23MB00219 | N33: C | O33: 8
I34: 33 | J34: 23MB00222 | L34: =J32 -> 23MB00220 | N34: C | O34: 9
I35: 34 | J35: 23MB00223 | L35: =J33 -> 23MB00221 | N35: C | O35: 10
I36: 35 | J36: 23MB00224 | L36: =J34 -> 23MB00222 | N36: C | O36: 11
I37: 36 | J37: 23MB00225 | L37: VTM-3 | M37: negative control | N37: C | O37: 12
I38: 37 | J38: 23MB00226 | L38: =J35 -> 23MB00223 | N38: D | O38: 1
I39: 38 | J39: 23MB00227 | L39: =J36 -> 23MB00224 | N39: D | O39: 2
I40: 39 | J40: 23MB00228 | L40: =J37 -> 23MB00225 | N40: D | O40: 3
...

Sheet RTPCR
A1: RT-PCR
A2: Date
A4: Plate Name | B4: =CONCATENATE("RTPCR_",Extraction!$B$2,"_",Extraction!$B$4) -> RTPCR_20241212_
A6: Initials
B9: 1 | C9: 2 | D9: 3 | E9: 4 | F9: 5 | G9: 6 | H9: 7 | I9: 8 | J9: 9 | K9: 10 | L9: 11 | M9: 12
A10: A | B10: =Extraction!$L2 -> 22MB00150 | C10: =Extraction!$L3 -> 22MB00151 | D10: =Extraction!$L4 -> 22MB00152 | E10: =Extraction!$L5 -> 22MB00153 | F10: =Extraction!$L6 -> 22MB00154 | G10: =Extraction!$L7 -> 22MB00155 | H10: =Extraction!$L8 -> 22MB00156 | I10: =Extraction!$L9 -> 22MB00157 | J10: =Extraction!$L10 -> 22MB00158 | K10: =Extraction!$L11 -> 22MB00159 | L10: =Extraction!$L12 -> 22MB00160 | M10: =Extraction!$L13 -> VTM-1
A11: B | B11: =Extraction!$L14 -> 23MB00201 | C11: =Extraction!$L15 -> 23MB00202 | D11: =Extraction!$L16 -> 23MB00203 | E11: =Extraction!$L17 -> 23MB00204 | F11: =Extraction!$L18 -> 23MB00205 | G11: =Extraction!$L19 -> 23MB00206 | H11: =Extraction!$L20 -> 23MB00207 | I11: =Extraction!$L21 -> 23MB00208 | J11: =Extraction!$L22 -> 23MB00209 | K11: =Extraction!$L23 -> 23MB00210 | L11: =Extraction!$L24 -> 23MB00211 | M11: =Extraction!$L25 -> VTM-2
A12: C | B12: =Extraction!$L26 -> 23MB00212 | C12: =Extraction!$L27 -> 23MB00213 | D12: =Extraction!$L28 -> 23MB00214 | E12: =Extraction!$L29 -> 23MB00215 | F12: =Extraction!$L30 -> 23MB00216 | G12: =Extraction!$L31 -> 23MB00217 | H12: =Extraction!$L32 -> 23MB00218 | I12: =Extraction!$L33 -> 23MB00219 | J12: =Extraction!$L34 -> 23MB00220 | K12: =Extraction!$L35 -> 23MB00221 | L12: =Extraction!$L36 -> 23MB00222 | M12: =Extraction!$L37 -> VTM-3
A13: D | B13: =Extraction!$L38 -> 23MB00223 | C13: =Extraction!$L39 -> 23MB00224 | D13: =Extraction!$L40 -> 23MB00225 | E13: =Extraction!$L41 -> 23MB00226 | F13: =Extraction!$L42 -> 23MB00227 | G13: =Extraction!$L43 -> 23MB00228 | H13: =Extraction!$L44 -> 23MB00229 | I13: =Extraction!$L45 -> 23MB00230 | J13: =Extraction!$L46 -> 23MB00231 | K13: =Extraction!$L47 -> 23MB00232 | L13: =Extraction!$L48 -> 23MB00233 | M13: =Extraction!$L49 -> VTM-4
A14: E | B14: =Extraction!$L50 -> 23MB00234 | C14: =Extraction!$L51 -> 23MB00235 | D14: =Extraction!$L52 -> 23MB00236 | E14: =Extraction!$L53 -> 23MB00237 | F14: =Extraction!$L54 -> 23MB00238 | G14: =Extraction!$L55 -> 23MB00239 | H14: =Extraction!$L56 -> 23MB00240 | I14: =Extraction!$L57 -> 23MB00241 | J14: =Extraction!$L58 -> 23MB00242 | K14: =Extraction!$L59 -> 23MB00243 | L14: =Extraction!$L60 -> 23MB00244 | M14: =Extraction!$L61 -> VTM-5
A15: F | B15: =Extraction!$L62 -> 23MB00245 | C15: =Extraction!$L63 -> 23MB00246 | D15: =Extraction!$L64 -> 23MB00247 | E15: =Extraction!$L65 -> 23MB00248 | F15: =Extraction!$L66 -> 23MB00249 | G15: =Extraction!$L67 -> 23MB00250 | H15: =Extraction!$L68 -> 23MB00251 | I15: =Extraction!$L69 -> 23MB00252 | J15: =Extraction!$L70 -> 23MB00253 | K15: =Extraction!$L71 -> 23MB00254 | L15: =Extraction!$L72 -> 23MB00255 | M15: =Extraction!$L73 -> VTM-6
A16: G | B16: =Extraction!$L74 -> 23MB00256 | C16: =Extraction!$L75 -> 23MB00257 | D16: =Extraction!$L76 -> 23MB00258 | E16: =Extraction!$L77 -> 23MB00259 | F16: =Extraction!$L78 -> 23MB00260 | G16: =Extraction!$L79 -> 23MB00261 | H16: =Extraction!$L80 -> 23MB00262 | I16: =Extraction!$L81 -> 23MB00263 | J16: =Extraction!$L82 -> 23MB00264 | K16: =Extraction!$L83 -> 23MB00265 | L16: =Extraction!$L84 -> 23MB00266 | M16: =Extraction!$L85 -> PR8
A17: H | B17: =Extraction!$L86 -> 23MB00267 | C17: =Extraction!$L87 -> 23MB00268 | D17: =Extraction!$L88 -> 23MB00269 | E17: =Extraction!$L89 -> 23MB00270 | F17: =Extraction!$L90 -> 23MB00271 | G17: =Extraction!$L91 -> 23MB00272 | H17: =Extraction!$L92 -> 23MB00273 | I17: =Extraction!$L93 -> 23MB00274 | J17: =Extraction!$L94 -> 23MB00275 | K17: =Extraction!$L95 -> 23MB00276 | L17: =Extraction!$L96 -> 23MB00277 | M17: PR8
A20: Reagent notes | B20: Reagent | D20: Calculations | G20: Date written on label (1st aliquot/bottle) | J20: Date written on label (2nd aliquot/bottle) | M20: Date written on label (3rd aliquot/bottle)
B22: Toughmix
B24: nuclease-free water
B26: forward primer
B28: reverse primer
B30: probe
B32: cDNA positive control (PR8)
A36: Plate notes

Sheet QS5
A1: * Block Type = 96-Well 0.1-mL Block
A2: * Date Created = Wed Jan 04 12:44:52 EST 2023
A3: * Passive Reference = ROX
A4: * Barcode =
A6: [Sample Setup]
A7: Well | B7: Well Position | C7: Sample Name | D7: Sample Color | E7: Biogroup Name | F7: Biogroup Color | G7: Target Name | H7: Target Color | I7: Task | J7: Reporter | K7: Quencher | L7: Quantity | M7: Comments
A8: 1 | B8: A1 | C8: =Extraction!L2 -> 22MB00150
A9: 2 | B9: A2 | C9: =Extraction!L3 -> 22MB00151
A10: 3 | B10: A3 | C10: =Extraction!L4 -> 22MB00152
A11: 4 | B11: A4 | C11: =Extraction!L5 -> 22MB00153
A12: 5 | B12: A5 | C12: =Extraction!L6 -> 22MB00154
A13: 6 | B13: A6 | C13: =Extraction!L7 -> 22MB00155
A14: 7 | B14: A7 | C14: =Extraction!L8 -> 22MB00156
A15: 8 | B15: A8 | C15: =Extraction!L9 -> 22MB00157
A16: 9 | B16: A9 | C16: =Extraction!L10 -> 22MB00158
A17: 10 | B17: A10 | C17: =Extraction!L11 -> 22MB00159
A18: 11 | B18: A11 | C18: =Extraction!L12 -> 22MB00160
A19: 12 | B19: A12 | C19: =Extraction!L13 -> VTM-1
... A103: 96 | B103: H12 | C103: =Extraction!L97 -> PR8

Sheet Sheet1
